Workbook

Sheet Right motor curve
A1: Motor Effort (pwm %) | B1: Steady State speed (enc counts/s) | C1: Speed (mm/s) | E1: Speed (rad/s)
A2: 10 | B2: =right_motor_10!D40 -> 470.3337 | C2: =B2*0.153 -> 71.961056 | D2: =B2*(2*PI()*35/1437.12) -> 71.97157 | E2: =D2/35 -> 2.0563306
A3: 20 | B3: =right_motor_20!D39 -> 1079.0327 | C3: =B3*0.153 -> 165.09201 | D3: =B3*(2*PI()*35/1437.12) -> 165.11613 | E3: =D3/35 -> 4.7176036
A4: 30 | B4: =right_motor_30!D41 -> 1748.9647 | C4: =B4*0.153 -> 267.5916 | D4: =B4*(2*PI()*35/1437.12) -> 267.6307 | E4: =D4/35 -> 7.6465914
A5: 40 | B5: =right_motor_40!D36 -> 2387.6189 | C5: =B5*0.153 -> 365.30569 | D5: =B5*(2*PI()*35/1437.12) -> 365.35907 | E5: =D5/35 -> 10.43883
A6: 50 | B6: =right_motor_50!D37 -> 3031.0419 | C6: =B6*0.153 -> 463.74941 | D6: =B6*(2*PI()*35/1437.12) -> 463.81716 | E6: =D6/35 -> 13.251919
A7: 60 | B7: =right_motor_60!D38 -> 3631.8141 | C7: =B7*0.153 -> 555.66756 | D7: =B7*(2*PI()*35/1437.12) -> 555.74874 | E7: =D7/35 -> 15.878536
A8: 70 | B8: =right_motor_70!D39 -> 4183.1518 | C8: =B8*0.153 -> 640.02222 | D8: =B8*(2*PI()*35/1437.12) -> 640.11573 | E8: =D8/35 -> 18.289021
A9: 80 | B9: =right_motor_80!D38 -> 4676.8773 | C9: =B9*0.153 -> 715.56222 | D9: =B9*(2*PI()*35/1437.12) -> 715.66677 | E9: =D9/35 -> 20.447622
A10: 90 | B10: =right_motor_90!D41 -> 5216.9948 | C10: =B10*0.153 -> 798.2002 | D10: =B10*(2*PI()*35/1437.12) -> 798.31682 | E10: =D10/35 -> 22.809052
A11: 100 | B11: =right_motor_100!D43 -> 5657.7009 | C11: =B11*0.153 -> 865.62824 | D11: =B11*(2*PI()*35/1437.12) -> 865.75471 | E11: =D11/35 -> 24.735849
A19: Motor Effort (pwm %) | B19: Speed (mm/s)
A20: 10 | B20: 71.961056
A21: 20 | B21: 165.09201
A22: 30 | B22: 267.5916
A23: 40 | B23: 365.30569
A24: 50 | B24: 463.74941
A25: 60 | B25: 555.66756
A26: 70 | B26: 640.02222
A27: 80 | B27: 715.56222
A28: 90 | B28: 798.2002
A29: 100 | B29: 865.62824
A32: Motor Effort (pwm %) | B32: Speed (rad/s)
A33: 10 | B33: 2.0563306
A34: 20 | B34: 4.7176036
A35: 30 | B35: 7.6465914
A36: 40 | B36: 10.43883
A37: 50 | B37: 13.251919
A38: 60 | B38: 15.878536
A39: 70 | B39: 18.289021
A40: 80 | B40: 20.447622
A41: 90 | B41: 22.809052
A42: 100 | B42: 24.735849
D43: Max motor voltage
A44: Motor Voltage | B44: Speed (rad/s) | D44: 9
A45: =A33*0.01*$D$44 -> 0.9 | B45: 2.0563306
A46: =A34*0.01*$D$44 -> 1.8 | B46: 4.7176036
A47: =A35*0.01*$D$44 -> 2.7 | B47: 7.6465914
A48: =A36*0.01*$D$44 -> 3.6 | B48: 10.43883
A49: =A37*0.01*$D$44 -> 4.5 | B49: 13.251919
...

Sheet right_motor_10
A1: 95042 | B1: 0
A2: 144987 | B2: 0
A3: 194936 | B3: 0
A4: 244884 | B4: 0
A5: 295270 | B5: 0
A6: 345229 | B6: 0
A7: 395469 | B7: 0
A8: 445060 | B8: 201.6454
A9: 495037 | B9: 240.1153
A10: 545016 | B10: 360.1585
A11: 595417 | B11: 436.4993
A12: 644886 | B12: 444.7229
... A39: 1995317 | B39: 479.5971
A40: 2045363 | B40: 479.5684 | D40: =AVERAGE(B36:B56) -> 470.3337
A41: 2095283 | B41: 460.7464
A42: 2145330 | B42: 459.568
A43: 2195382 | B43: 459.5313
A44: 2245435 | B44: 439.5429
A45: 2294940 | B45: 464.6183
A46: 2344997 | B46: 439.5078
A47: 2394926 | B47: 460.6541
A48: 2444986 | B48: 459.4579
A49: 2495050 | B49: 479.396
A50: 2545115 | B50: 479.3864
A51: 2595184 | B51: 459.3661
A52: 2645299 | B52: 478.8985
... A56: 2845480 | B56: 479.2237

Sheet right_motor_20
A1: 95029 | B1: 0
A2: 144935 | B2: 0
A3: 194844 | B3: 0
A4: 244751 | B4: 0
A5: 295097 | B5: 0
A6: 345014 | B6: 0
A7: 395215 | B7: 0
A8: 444766 | B8: 443.978
A9: 495252 | B9: 594.2123
A10: 545187 | B10: 881.1631
A11: 594998 | B11: 1003.815
A12: 644941 | B12: 1001.141
... A38: 1944831 | B38: 1080
A39: 1994833 | B39: 1079.957 | D39: =AVERAGE(B36:B56) -> 1079.0327
A40: 2044835 | B40: 1079.978
A41: 2095263 | B41: 1110.516
A42: 2144758 | B42: 1091.063
A43: 2194772 | B43: 1079.719
A44: 2244783 | B44: 1079.762
A45: 2294800 | B45: 1059.64
A46: 2344815 | B46: 1079.698
A47: 2395255 | B47: 1070.579
A48: 2445277 | B48: 1099.516
A49: 2495302 | B49: 1079.482
A50: 2544779 | B50: 1071.27
A51: 2594809 | B51: 1079.352
... A56: 2844854 | B56: 1059.153

Sheet right_motor_30
A1: 66494 | B1: 0
A2: 116433 | B2: 0
A3: 166490 | B3: 0
A4: 216549 | B4: 0
A5: 266613 | B5: 0
A6: 316133 | B6: 0
A7: 366482 | B7: 0
A8: 416604 | B8: 658.3804
A9: 466139 | B9: 969.0314
A10: 516229 | B10: 1317.681
A11: 566315 | B11: 1517.39
A12: 616408 | B12: 1616.992
... A40: 2016540 | B40: 1753.198
A41: 2066146 | B41: 1753.926 | D41: =AVERAGE(B37:B57) -> 1748.9647
A42: 2116303 | B42: 1754.491
A43: 2166464 | B43: 1754.351
A44: 2216498 | B44: 1738.818
A45: 2266663 | B45: 1754.246
A46: 2316283 | B46: 1773.586
A47: 2366450 | B47: 1754.106
A48: 2416621 | B48: 1754.001
A49: 2466245 | B49: 1753.29
A50: 2516293 | B50: 1758.312
A51: 2566471 | B51: 1753.757
A52: 2616652 | B52: 1753.687
A53: 2666285 | B53: 1732.788
... A57: 2866362 | B57: 1753.267

Sheet right_motor_40
A1: 86336 | B1: 0
A2: 136373 | B2: 0
A3: 186410 | B3: 0
A4: 236334 | B4: 0
A5: 286378 | B5: 0
A6: 336426 | B6: 0
A7: 386756 | B7: 0
A8: 436442 | B8: 865.4349
A9: 486509 | B9: 1418.071
A10: 536448 | B10: 1722.17
A11: 586559 | B11: 2035.481
A12: 636628 | B12: 2176.996
... A35: 1786769 | B35: 2394.158
A36: 1836346 | B36: 2400.452 | D36: =AVERAGE(B36:B56) -> 2387.6189
A37: 1886471 | B37: 2413.965
A38: 1936601 | B38: 2373.828
A39: 1986732 | B39: 2373.828
A40: 2036738 | B40: 2359.764
A41: 2086323 | B41: 2379.8
A42: 2136463 | B42: 2393.346
A43: 2186604 | B43: 2373.26
A44: 2236748 | B44: 2373.26
A45: 2286341 | B45: 2399.581
A46: 2336361 | B46: 2419.081
A47: 2386512 | B47: 2372.787
A48: 2436670 | B48: 2392.488
... A56: 2836789 | B56: 2411.656

Sheet right_motor_50
A1: 56468 | B1: 0
A2: 106553 | B2: 0
A3: 156641 | B3: 0
A4: 206727 | B4: 0
A5: 256816 | B5: 0
A6: 306358 | B6: 0
A7: 356334 | B7: 0
A8: 406713 | B8: 0
A9: 456448 | B9: 1045.499
A10: 506558 | B10: 1796.049
A11: 556677 | B11: 2075.144
A12: 606794 | B12: 2474.21
... A36: 1806523 | B36: 3040.86
A37: 1856566 | B37: 3037.388 | D37: =AVERAGE(B36:B57) -> 3031.0419
A38: 1906739 | B38: 3029.639
A39: 1956366 | B39: 3022.67
A40: 2006545 | B40: 3029.095
A41: 2056728 | B41: 3009.047
A42: 2106361 | B42: 3022.305
A43: 2156417 | B43: 3036.599
A44: 2206606 | B44: 3008.627
A45: 2256800 | B45: 3048.234
A46: 2306440 | B46: 3062.17
A47: 2356637 | B47: 3028.009
A48: 2406836 | B48: 3028.009
A49: 2456355 | B49: 3029.324
... A57: 2856839 | B57: 3026.864

Sheet right_motor_60
A1: 94954 | B1: 0
A2: 145249 | B2: 0
A3: 194997 | B3: 0
A4: 245295 | B4: 0
A5: 294928 | B5: 0
A6: 345236 | B6: 0
A7: 395272 | B7: 0
A8: 445216 | B8: 1161.254
A9: 494989 | B9: 2129.669
A10: 545354 | B10: 2581.157
A11: 595003 | B11: 2880.393
A12: 645331 | B12: 3179.145
... A37: 1895014 | B37: 3632.131
A38: 1945403 | B38: 3611.899 | D38: =AVERAGE(B36:B56) -> 3631.8141
A39: 1995242 | B39: 3631.84
A40: 2045081 | B40: 3651.832
A41: 2095349 | B41: 3640.559
A42: 2145194 | B42: 3671.381
A43: 2195043 | B43: 3651.099
A44: 2244891 | B44: 3651.026
A45: 2295295 | B45: 3630.88
A46: 2345151 | B46: 3610.398
A47: 2394879 | B47: 3659.836
A48: 2445292 | B48: 3610.395
A49: 2495156 | B49: 3650.001
A50: 2545020 | B50: 3649.928
... A56: 2845268 | B56: 3609.023

Sheet right_motor_70
A1: 85835 | B1: 0
A2: 135872 | B2: 0
A3: 185915 | B3: 0
A4: 235855 | B4: 0
A5: 285914 | B5: 0
A6: 335980 | B6: 0
A7: 386329 | B7: 0
A8: 436033 | B8: 1247.334
A9: 486125 | B9: 2435.713
A10: 536091 | B10: 2922.045
A11: 585643 | B11: 3228.996
A12: 635793 | B12: 3549.706
... A38: 1936243 | B38: 4162.766
A39: 1985928 | B39: 4187.048 | D39: =AVERAGE(B36:B56) -> 4183.1518
A40: 2036032 | B40: 4211.493
A41: 2086269 | B41: 4180.103
A42: 2135954 | B42: 4186.374
A43: 2186196 | B43: 4159.949
A44: 2235888 | B44: 4185.869
A45: 2286135 | B45: 4159.618
A46: 2336257 | B46: 4209.728
A47: 2385956 | B47: 4205.401
A48: 2436212 | B48: 4198.504
A49: 2485915 | B49: 4144.703
A50: 2536174 | B50: 4158.542
A51: 2585893 | B51: 4184.353
... A56: 2835960 | B56: 4190.392

Sheet right_motor_80
A1: 94806 | B1: 0
A2: 144985 | B2: 0
A3: 194617 | B3: 0
A4: 244804 | B4: 0
A5: 294914 | B5: 0
A6: 344554 | B6: 0
A7: 395030 | B7: 0
A8: 444858 | B8: 1444.942
A9: 495065 | B9: 2688.815
A10: 544725 | B10: 3322.728
A11: 594808 | B11: 3733.876
A12: 645026 | B12: 3982.715
... A37: 1894625 | B37: 4666.318
A38: 1944901 | B38: 4694.369 | D38: =AVERAGE(B36:B56) -> 4676.8773
A39: 1994624 | B39: 4665.755
A40: 2044905 | B40: 4654.031
A41: 2095055 | B41: 4646.062
A42: 2144789 | B42: 4665.004
A43: 2195075 | B43: 4693.155
A44: 2244813 | B44: 4684.547
A45: 2294595 | B45: 4700.589
A46: 2344890 | B46: 4652.735
A47: 2395053 | B47: 4644.858
A48: 2444801 | B48: 4643.403
A49: 2495101 | B49: 4691.849
A50: 2544849 | B50: 4703.99
... A56: 2844929 | B56: 4690.729

Sheet right_motor_90
A1: 86726 | B1: 0
A2: 136641 | B2: 0
A3: 186558 | B3: 0
A4: 236359 | B4: 0
A5: 286834 | B5: 0
A6: 336761 | B6: 0
A7: 386971 | B7: 0
A8: 436533 | B8: 1553.578
A9: 486475 | B9: 3003.484
A10: 536846 | B10: 3732.38
A11: 586795 | B11: 4024.346
A12: 636745 | B12: 4204.204
... A40: 2036812 | B40: 5212.301
A41: 2086830 | B41: 5218.226 | D41: =AVERAGE(B36:B56) -> 5216.9948
A42: 2136850 | B42: 5198.025
A43: 2186867 | B43: 5218.121
A44: 2236888 | B44: 5197.817
A45: 2286916 | B45: 5217.287
A46: 2336811 | B46: 5231.195
A47: 2386841 | B47: 5196.986
A48: 2436872 | B48: 5196.57
A49: 2486907 | B49: 5196.57
A50: 2536940 | B50: 5216.557
A51: 2586426 | B51: 5254.117
A52: 2636887 | B52: 5231.763
A53: 2686931 | B53: 5235.497
... A56: 2836561 | B56: 5234.87

Sheet right_motor_100
A1: 95252 | B1: 0
A2: 145354 | B2: 0
A3: 195458 | B3: 0
A4: 245009 | B4: 0
A5: 295000 | B5: 0
A6: 345110 | B6: 0
A7: 395507 | B7: 0
A8: 445295 | B8: 1566.517
A9: 495425 | B9: 3291.508
A10: 545004 | B10: 4215.58
A11: 595010 | B11: 4579.542
A12: 645148 | B12: 4726.954
... A42: 2145256 | B42: 5677.291
A43: 2195463 | B43: 5696.417 | D43: =AVERAGE(B36:B56) -> 5657.7009
A44: 2245118 | B44: 5659.275
A45: 2295327 | B45: 5636.439
A46: 2345544 | B46: 5675.708
A47: 2395079 | B47: 5692.83
A48: 2445339 | B48: 5710.307
A49: 2495561 | B49: 5675.03
A50: 2545229 | B50: 5637.433
A51: 2595452 | B51: 5634.981
A52: 2645129 | B52: 5656.542
A53: 2695228 | B53: 5668.889
A54: 2745456 | B54: 5634.419
A55: 2795138 | B55: 5615.716
A56: 2845372 | B56: 5633.747
